<mujoco model='exoskeleton'>
            <compiler meshdir="obj-files" angle="degree" autolimits="true"/>
            <size nuser_actuator='1' nuser_sensor='8' nuser_geom='1'/>
            <option timestep="0.02" iterations="5" ls_iterations="10" gravity='0 0 -9.81'>
                <flag multiccd="disable"/>
            </option>

            <visual>
                <map force="0.1" zfar="30"/>
                <rgba haze="0.15 0.25 0.35 1"/>
                <quality shadowsize="4096"/>
                <global offwidth="800" offheight="800"/>
            </visual>
           
    
            <default>
                <site group="5" />
                <motor ctrlrange="-1 1" ctrllimited="true" />
                <geom contype="0" conaffinity="0" condim="1" solref="0.005 1" />
                <equality solref="0.005 1" />
            </default>
       
            <!-- Nested defaults for exoskeleton, collisions, and joints -->
            <default>
                <default class="exoskeleton">
                <geom material="march_grey" group="2" contype="0" conaffinity="0"/>
                </default>
                <default class= "humanoid">
                <geom material="march_grey" group="1" contype="0" conaffinity="0"/>
                </default>
                <default class ="foot_collision">
                  <geom group="3" contype="1" conaffinity="1" friction = "1" rgba="1 1 1 0.5"/>
                </default>

                <default class="collision">
                <geom type="capsule" group="3" contype="1" conaffinity="1" rgba="1 1 1 0.5"/>
                </default>

                <default class="L_collision">
                <geom type="capsule" group="3" contype="2" conaffinity="4" rgba="1 1 1 0.5"/>
                </default>

                <default class="R_collision">
                <geom type="capsule" group="3" contype="4" conaffinity="2" rgba="1 1 1 0.5"/>
                </default>

                <default class="HAA_joint">
                <joint damping="107.692308" armature="5.4" frictionloss="5" stiffness="0"/>
                </default>

                <default class="ADPF_joint">
                <joint damping="43.658537" armature="2.2" frictionloss="5" stiffness="0"/>
                </default>

                <default class="rotational_joint">
                <joint damping="63.451777" armature="9.98" frictionloss="5" stiffness="0"/>
                </default>

                <default class="AIE_joint">
                <joint damping="63.451777" armature="2.2" frictionloss="5" stiffness="0"/>
                </default>
            </default>
        
            <asset>
                <texture type="skybox" builtin="gradient" rgb1=".3 .5 .7" rgb2="0 0 0" width="512" height="512"/>
                <texture name="body" type="cube" builtin="flat" mark="cross" width="127" height="1278"
                        rgb1="0.8 0.6 0.4" rgb2="0.8 0.6 0.4" markrgb="1 1 1" random="0.01"/>
                <texture name="grid" type="2d" builtin="checker" width="512" height="512" rgb1=".1 .2 .3" rgb2=".2 .3 .4"/>
                <material name="grid" texture="grid" texrepeat="1 1" texuniform="true" reflectance=".2"/>
                <material name="march_grey" rgba=".87 .89 .91 1"/>
                <material name="collision" rgba="1 0 0 1"/>

                <mesh name="backpack"    scale="-1 1 1"   file="Backplate.obj"/>
                <mesh name="L_Ankle"     scale="-1 -1 1"   file="L_Ankle.obj"/>
                <mesh name="L_Hip"       scale="-1 -1 1"   file="L_Hip.obj"/>
                <mesh name="L_UpperLeg"  scale="-1 -1 1"   file="L_UpperLeg.obj"/>
                <mesh name="L_LowerLeg"  scale="-1 -1 1"   file="L_LowerLeg.obj"/>
                <mesh name="L_Sole"      scale="-1 -1 1"   file="L_Foot.obj"/>

                <mesh name="R_Ankle"     scale="-1 1 1"    file="L_Ankle.obj"/>
                <mesh name="R_Hip"       scale="-1 1 1"    file="L_Hip.obj"/>
                <mesh name="R_UpperLeg"  scale="-1 1 1"    file="L_UpperLeg.obj"/>
                <mesh name="R_LowerLeg"  scale="-1 1 1"    file="L_LowerLeg.obj"/>
                <mesh name="R_Sole"      scale="-1 1 1"    file="L_Foot.obj"/>
            </asset>
        
  <actuator>
    <motor name="left_ankle_ie" gear="100" joint="left_ankle_ie" />
    <motor name="left_ankle_dpf" gear="100" joint="left_ankle_dpf" />
    <motor name="left_hip_aa" gear="100" joint="left_hip_aa" />
    <motor name="left_hip_fe" gear="100" joint="left_hip_fe" />
    <motor name="left_knee" gear="100" joint="left_knee" />
    <motor name="right_ankle_ie" gear="100" joint="right_ankle_ie" />
    <motor name="right_ankle_dpf" gear="100" joint="right_ankle_dpf" />
    <motor name="right_hip_aa" gear="100" joint="right_hip_aa" />
    <motor name="right_hip_fe" gear="100" joint="right_hip_fe" />
    <motor name="right_knee" gear="100" joint="right_knee" />

  </actuator>
            
            <sensor>
    <!-- <jointpos name="L_AIE_pos_output" joint="left_ankle_ie" user="18" noise="000" />
    <jointpos name="L_ADPF_pos_output" joint="left_ankle_dpf" user="18" noise="000" />
    <jointpos name="L_HAA_pos_output" joint="left_hip_aa" user="18" noise="000" />
    <jointpos name="L_HFE_pos_output" joint="left_hip_fe" user="18" noise="000" />
    <jointpos name="L_KFE_pos_output" joint="left_knee" user="18" noise="000" />
    <jointpos name="R_AIE_pos_output" joint="right_ankle_ie" user="18" noise="000" />
    <jointpos name="R_ADPF_pos_output" joint="right_ankle_dpf" user="18" noise="000" />
    <jointpos name="R_HAA_pos_output" joint="right_hip_aa" user="18" noise="000" />
    <jointpos name="R_HFE_pos_output" joint="right_hip_fe" user="18" noise="000" />
    <jointpos name="R_KFE_pos_output" joint="right_knee" user="18" noise="000" />

    <jointvel name="L_AIE_vel_output" joint="left_ankle_ie" user="18" noise="000" />
    <jointvel name="L_ADPF_vel_output" joint="left_ankle_dpf" user="18" noise="000" />
    <jointvel name="L_HAA_vel_output" joint="left_hip_aa" user="18" noise="000" />
    <jointvel name="L_HFE_vel_output" joint="left_hip_fe" user="18" noise="000" />
    <jointvel name="L_KFE_vel_output" joint="left_knee" user="18" noise="000" />
    <jointvel name="R_AIE_vel_output" joint="right_ankle_ie" user="18" noise="000" />
    <jointvel name="R_ADPF_vel_output" joint="right_ankle_dpf" user="18" noise="000" />
    <jointvel name="R_HAA_vel_output" joint="right_hip_aa" user="18" noise="000" />
    <jointvel name="R_HFE_vel_output" joint="right_hip_fe" user="18" noise="000" />
    <jointvel name="R_KFE_vel_output" joint="right_knee" user="18" noise="000" />

    <torque name="L_AIE_tor_output" site="tor_L_AIE" user="13" noise="000" />
    <torque name="L_ADPF_tor_output" site="tor_L_ADPF" user="13" noise="000" />
    <torque name="L_HAA_tor_output" site="tor_L_HAA" user="13" noise="000" />
    <torque name="L_HFE_tor_output" site="tor_L_HFE" user="13" noise="000" />
    <torque name="L_KFE_tor_output" site="tor_L_KFE" user="13" noise="000" />
    <torque name="R_AIE_tor_output" site="tor_R_AIE" user="13" noise="000" />
    <torque name="R_ADPF_tor_output" site="tor_R_ADPF" user="13" noise="000" />
    <torque name="R_HAA_tor_output" site="tor_R_HAA" user="13" noise="000" />
    <torque name="R_HFE_tor_output" site="tor_R_HFE" user="13" noise="000" />
    <torque name="R_KFE_tor_output" site="tor_R_KFE" user="13" noise="000" /> -->

        <!-- ZMP sensors right foot-->
     <!--Back left  -->
    <framepos name="R_foot_pos_bl" objtype="geom" objname="R_foot_contact_bl"/>
    <!--Back right  -->
    <framepos name="R_foot_pos_br" objtype="geom" objname="R_foot_contact_br"/>
    <!--Front left  -->
    <framepos name="R_foot_pos_fl" objtype="geom" objname="R_foot_contact_fl"/>
    <!--Front right  -->
    <framepos name="R_foot_pos_fr" objtype="geom" objname="R_foot_contact_fr"/>

    <!-- ZMP sensors left foot-->
    <framepos name="L_foot_pos_bl" objtype="geom" objname="L_foot_contact_bl"/>
    <framepos name="L_foot_pos_br" objtype="geom" objname="L_foot_contact_br"/>
    <framepos name="L_foot_pos_fl" objtype="geom" objname="L_foot_contact_fl"/>
    <framepos name="L_foot_pos_fr" objtype="geom" objname="L_foot_contact_fr"/>

                <!-- Noise & cutoff must be determined -->
                <!-- Noise & cutoff must be determined -->
              <framequat name='backpack_orientation' objtype='site' objname='imu_backpack'/>
              <gyro name='vel_imu_backpack' site='imu_backpack' noise='0' cutoff='34.9'/>
              <accelerometer name='acc_imu_backpack' site='imu_backpack' noise='0' cutoff='157'/>
              <subtreecom name="torso_subtreecom" body="backpack"/>
              <framequat name='L_UL_orientation' objtype='site' objname='L_UL_imu'/>
              <gyro name='vel_L_UL_imu' site='L_UL_imu' noise='0' cutoff='34.9'/>
              <accelerometer name='acc_L_UL_imu' site='L_UL_imu' noise='0' cutoff='157'/>
              
              <framequat name='L_LL_orientation' objtype='site' objname='L_LL_imu'/>
              <gyro name='vel_L_LL_imu' site='L_LL_imu' noise='0' cutoff='34.9'/>
              <accelerometer name='acc_L_LL_imu' site='L_LL_imu' noise='0' cutoff='157'/>
              
              <framequat name="R_UL_orientation" objtype="site" objname="R_UL_imu"/>
              <gyro name="vel_R_UL_imu" site="R_UL_imu" noise="0" cutoff="34.9"/>
              <accelerometer name="acc_R_UL_imu" site="R_UL_imu" noise="0" cutoff="157"/>
              
              <framequat name="R_LL_orientation" objtype="site" objname="R_LL_imu"/>
              <gyro name="vel_R_LL_imu" site="R_LL_imu" noise="0" cutoff="34.9"/>
              <accelerometer name="acc_R_LL_imu" site="R_LL_imu" noise="0" cutoff="157"/>
              
              <framequat name="L_hip_orientation" objtype="site" objname="L_hip_imu"/>
              <gyro name="vel_L_hip_imu" site="L_hip_imu" noise="0" cutoff="34.9"/>
              <accelerometer name="acc_L_hip_imu" site="L_hip_imu" noise="0" cutoff="157"/>
              
              <framequat name="R_hip_orientation" objtype="site" objname="R_hip_imu"/>
              <gyro name="vel_R_hip_imu" site="R_hip_imu" noise="0" cutoff="34.9"/>
              <accelerometer name="acc_R_hip_imu" site="R_hip_imu" noise="0" cutoff="157"/>
              
              <framequat name="L_ankle_orientation" objtype="site" objname="L_ankle_imu"/>
              <gyro name="vel_L_ankle_imu" site="L_ankle_imu" noise="0" cutoff="34.9"/>
              <accelerometer name="acc_L_ankle_imu" site="L_ankle_imu" noise="0" cutoff="157"/>
              
              <framequat name="R_ankle_orientation" objtype="site" objname="R_ankle_imu"/>
              <gyro name="vel_R_ankle_imu" site="R_ankle_imu" noise="0" cutoff="34.9"/>
              <accelerometer name="acc_R_ankle_imu" site="R_ankle_imu" noise="0" cutoff="157"/>
              
              <framequat name="L_foot_orientation" objtype="site" objname="L_foot_imu"/>
              <gyro name="vel_L_foot_imu" site="L_foot_imu" noise="0" cutoff="34.9"/>
              <accelerometer name="acc_L_foot_imu" site="L_foot_imu" noise="0" cutoff="157"/>
              
              <framequat name="R_foot_orientation" objtype="site" objname="R_foot_imu"/>
              <gyro name="vel_R_foot_imu" site="R_foot_imu" noise="0" cutoff="34.9"/>
              <accelerometer name="acc_R_foot_imu" site="R_foot_imu" noise="0" cutoff="157"/>
              
              <!-- Human body IMUs -->
              <framequat name="torso_orientation" objtype="site" objname="torso_imu"/>
              <gyro name="vel_torso_imu" site="torso_imu" noise="0" cutoff="34.9"/>
              <accelerometer name="acc_torso_imu" site="torso_imu" noise="0" cutoff="157"/>
              
              <framequat name="right_arm_orientation" objtype="site" objname="right_arm_imu"/>
              <gyro name="vel_right_arm_imu" site="right_arm_imu" noise="0" cutoff="34.9"/>
              <accelerometer name="acc_right_arm_imu" site="right_arm_imu" noise="0" cutoff="157"/>
              
              <framequat name="right_forearm_orientation" objtype="site" objname="right_forearm_imu"/>
              <gyro name="vel_right_forearm_imu" site="right_forearm_imu" noise="0" cutoff="34.9"/>
              <accelerometer name="acc_right_forearm_imu" site="right_forearm_imu" noise="0" cutoff="157"/>
              
              <framequat name="right_hand_orientation" objtype="site" objname="right_hand_imu"/>
              <gyro name="vel_right_hand_imu" site="right_hand_imu" noise="0" cutoff="34.9"/>
              <accelerometer name="acc_right_hand_imu" site="right_hand_imu" noise="0" cutoff="157"/>
              
              <framequat name="left_arm_orientation" objtype="site" objname="left_arm_imu"/>
              <gyro name="vel_left_arm_imu" site="left_arm_imu" noise="0" cutoff="34.9"/>
              <accelerometer name="acc_left_arm_imu" site="left_arm_imu" noise="0" cutoff="157"/>
              
              <framequat name="left_forearm_orientation" objtype="site" objname="left_forearm_imu"/>
              <gyro name="vel_left_forearm_imu" site="left_forearm_imu" noise="0" cutoff="34.9"/>
              <accelerometer name="acc_left_forearm_imu" site="left_forearm_imu" noise="0" cutoff="157"/>
              
              <framequat name="left_hand_orientation" objtype="site" objname="left_hand_imu"/>
              <gyro name="vel_left_hand_imu" site="left_hand_imu" noise="0" cutoff="34.9"/>
              <accelerometer name="acc_left_hand_imu" site="left_hand_imu" noise="0" cutoff="157"/>
              
              <framequat name="head_orientation" objtype="site" objname="head_imu"/>
              <gyro name="vel_head_imu" site="head_imu" noise="0" cutoff="34.9"/>
              <accelerometer name="acc_head_imu" site="head_imu" noise="0" cutoff="157"/>
                
                <!-- Pressure sensors for left foot -->
                <touch name="pressure_sp0" site="sp0" cutoff="1"/>
                <touch name="pressure_sp1" site="sp1" cutoff="1"/>
                <touch name="pressure_sp2" site="sp2" cutoff="1"/>
                <touch name="pressure_sp3" site="sp3" cutoff="1"/>
                
                <!-- Pressure sensors for right foot -->
                <touch name="pressure_sp4" site="sp4" cutoff="1"/>
                <touch name="pressure_sp5" site="sp5" cutoff="1"/>
                <touch name="pressure_sp6" site="sp6" cutoff="1"/>
                <touch name="pressure_sp7" site="sp7" cutoff="1"/>
            </sensor>
            <!-- <keyframe><key name='home' qpos='0 0 1.01 0.9990482 0 0.0436194 0 0 0.1519 0.3164 0.2236 -0.0 0 0.1519 0.3164 0.2236 -0.0'/></keyframe><worldbody><geom name='floor' size='0 0 .05' type='plane' material='grid' pos='0 0 0' conaffinity='15' condim='6' solref='0.000002 1' solimp='0.99 0.999 0.000001' friction='3 0.005 0.0001'/><light name='spotlight' mode='targetbodycom' target='backpack' diffuse='.8 .8 .8' specular='0.3 0.3 0.3' pos='0 -20 4' cutoff='10'/> -->
            <keyframe><key name='home' qpos='0 0 1.01 0.9990482 0 0.0436194 0 0.0538850788003355 0.163444867517726 0.3114220463634088 0.1834168026738673 0.0538736103022484 0.0538904247681917 0.1634221502873682 0.3113776463689615 0.1833954904567925 0.0538794144550795'/></keyframe><worldbody><geom name='floor' size='0 0 .05' type='plane' material='grid' pos='0 0 0' conaffinity='15' condim='6' solref='0.000002 1' solimp='0.99 0.999 0.000001' friction='3 0.005 0.0001'/><light name='spotlight' mode='targetbodycom' target='backpack' diffuse='.8 .8 .8' specular='0.3 0.3 0.3' pos='0 -20 4' cutoff='10'/>

            <body name="safety_catcher" pos="-0.4 0.0 1.03">
            <inertial pos="0 0 0" mass="0.1" diaginertia="10 10 10"/>
            
            <joint name='safety_catch_free' type='free'/>
                   
      <body name="backpack" pos="0.00000 0.00000 0.28000">
        <light name="top" pos="0.00000 0.00000 2.00000" mode="trackcom" />
        <camera name="diag" pos="3.00000 -2.50000 1.00000" xyaxes="1 1 0 0 1 2" mode="track" />
        <camera name="right" pos="0.00000 -3.00000 1.00000" xyaxes="1 0 0 0 1 2" mode="track" />
        <camera name="front" pos="4.00000 0.00000 0.00000" xyaxes="0 1 0 0 1 2" mode="track" />
        <inertial mass="3.205" pos="-0.00400 0 -0.01700" fullinertia="0.13140 0.04400 0.08870 -0.00000 -0.00100 0.00000" />
        <site name="imu_backpack" size="0.01" pos="-0.00400 0 -0.01700" />
        <geom name="backpack" type="mesh" mesh="backpack" />
        <geom name="backpack_ellipsoid" type="ellipsoid" size="0.12 0.18 0.25" material="march_grey" class="collision"/>
        <site name="pos_backpack" size="0.001" pos="0.00000 0.00000 0.00000" />

                
         <body name ="torso" pos="0.2 0 -0.3" >
          <geom name="torso" type="capsule" fromto="0 0 0.1 0 0 0.4" size="0.175" mass="43.2" class="humanoid"/>
          <site name="torso_imu" size="0.01" pos="0 0 0.25" />
        </body>

        <body name="right arm" pos="0.20 0.150 0.2" euler="25 0 0" >
          <geom name="right arm" type="capsule" fromto="0 0.105 -0.250 0 0 0" size="0.06" mass="3.38" class="humanoid"/>
          <site name="right_arm_imu" size="0.01" pos="0 0.0525 -0.125" />

          <body name="right forearm" pos="0 0.105 -0.280">
            <geom name="right forearm" type="capsule" fromto="0 0.065 -0.290 0 0 0" size="0.05" mass="1.15" class="humanoid"/>
            <site name="right_forearm_imu" size="0.01" pos="0 0.0325 -0.145" />

            <body name="right hand" pos="0 0.07 -0.300">
              <geom name="right hand" type="sphere" size="0.05" pos="0 0.0 -0.05" mass="0.9876" class="humanoid"/>
              <site name="right_hand_imu" size="0.01" pos="0 0 -0.05" />
            </body>
          </body>
        </body>

        <body name="left arm" pos="0.20 -0.150 0.2" euler="-25 0 0">
          <geom name="left arm" type="capsule" fromto="0 -0.105 -0.250 0 0 0" size="0.06" mass="3.38" class="humanoid"/>
          <site name="left_arm_imu" size="0.01" pos="0 -0.0525 -0.125" />

          <body name="left forearm" pos="0 -0.105 -0.280">
            <geom name="left forearm" type="capsule" fromto="0 -0.065 -0.290 0 0 0" size="0.05" mass="1.15" class="humanoid"/>
            <site name="left_forearm_imu" size="0.01" pos="0 -0.0325 -0.145" />
            <body name="left hand" pos="0 -0.07 -0.300">

              <geom name="left hand" type="sphere" size="0.05" pos="0 0 -0.05" mass="0.9876" class="humanoid"/>
              <site name="left_hand_imu" size="0.01" pos="0 0 -0.05" />
            </body>
          </body>
        </body>
                        
        <body name="head">
          <geom name="head" type="sphere" size="0.1" pos="0.2 0 0.37" mass="8" class="humanoid"/>
          <site name="head_imu" size="0.01" pos="0.2 0 0.37" />
        </body>
    
        

        <body name="L_hip" pos="0.00400 0.09200 -0.20000">
          <inertial mass="3.363" pos="0.12400 0.17000 0.00700" fullinertia="0.11230 0.08360 0.18680 -0.08410 -0.00300 -0.00320" />
          <joint name="left_hip_aa" axis="-1 0 0" range="-20 10" limited="true" class="HAA_joint" />
          <site name="tor_L_HAA" size="0.01" pos="0.00000 0.00000 0.00000" />
          <site name="pos_L_HAA" size="0.01" pos="0.00000 0.00000 0.00000" />
          <site name="L_hip_imu" size="0.01" pos="0.12400 0.17000 0.00700" />
          <geom name="L_Hip" type="mesh" mesh="L_Hip" />
         <geom name="L_Hip_ellipsoid" type="ellipsoid" size="0.10 0.12 0.08" pos="0.08 0.12 0" material="march_grey" class="L_collision"/>
          
          
         <body name="L_UL" pos="0.17600 0.24900 0.00100">
            <inertial mass="4.473" pos="0.02600 -0.07500 -0.23600" fullinertia="0.49120 0.46540 0.04310 0.00890 0.02870 -0.11260" />
            <joint name="left_hip_fe" axis="0 -1 0" range="-20 115" limited="true" class="rotational_joint" />
            <site name="tor_L_HFE" size="0.01" pos="0.00000 0.00000 0.00000" />
            <site name="pos_L_HFE" size="0.01" pos="0.00000 0.00000 0.00000" />
            <site name="L_UL_imu" size="0.01" pos="0.02600 -0.07500 -0.23600" />

            <geom name="L_UpperLeg" type="mesh" mesh="L_UpperLeg" />
            <geom name="L_UpperLeg_ellipsoid" type="ellipsoid" size="0.08 0.08 0.24" pos="0 -0.04 -0.235" material="march_grey" class="L_collision"/>



                    <body> <geom type="capsule" fromto="0 -0.125 0 0 -0.175 -0.45" size="0.075" mass="8.44"/> </body>
                    
             <body name="L_LL" pos="0.00200 -0.0600 -0.47200">
              <inertial mass="4.973" pos="0.00300 -0.04600 -0.14500" fullinertia="0.21540 0.22000 0.03000 0.00140 -0.00290 -0.03550" />
              <joint name="left_knee" axis="0 1 0" range="0 125" limited="true" class="rotational_joint" />
              <site name="tor_L_KFE" size="0.01" pos="0.00000 0.00000 0.00000" />
              <site name="pos_L_KFE" size="0.01" pos="0.00000 0.00000 0.00000" />
              <site name="L_LL_imu" size="0.01" pos="0.00300 -0.04600 -0.14500" />
              <geom name="L_LowerLeg" type="mesh" mesh="L_LowerLeg" />
              <geom name="L_LowerLeg_ellipsoid" type="ellipsoid" size="0.07 0.07 0.23" pos="0 -0.015 -0.23" material="march_grey" class="L_collision"/>


                    <body> <geom type="capsule" fromto="0 -0.1 0 0 -0.08 -0.5" size="0.05" mass="2.3"/> </body>

                <body name="L_ankle" pos="0.0000 -0.02500 -0.46800">
                <inertial mass="0.515" pos=" 0.00400 -0.06000 -0.01800" fullinertia="0.00240 0.00260 0.00460 0.00010 -0.00000 -0.00060" />
                <joint name="left_ankle_dpf" axis="0 -1 0" range="-28 17" limited="true" class="AIE_joint" />
                <site name="tor_L_ADPF" size="0.01" pos="0.00000 0.00000 0.00000" />
                <site name="tor_L_AIE" size="0.01" pos="-0.13100 -0.11400 -0.02600" />
                <site name="pos_L_ankle" size="0.01" pos="0.00000 0.00000 0.00000" />
                <site name="L_ankle_imu" size="0.01" pos="0.00400 -0.06000 -0.01800" />
                
                <geom name="L_Ankle" type="mesh" mesh="L_Ankle" />
                <geom name="L_Ankle_ellipsoid" type="ellipsoid" size="0.07 0.06 0.04" pos="0 -0.06 -0.015" material="march_grey" class="L_collision"/>

               <body name="L_foot" pos="-0.13500 -0.1200 -0.02600">
                  <inertial mass="4.440" pos=" 0.16300 0.02400 -0.06000" fullinertia="0.04700 0.19090 0.17630 -0.01390 0.04760 -0.00130" />
                  <joint name="left_ankle_ie" pos="-0.0 -0.0 -0.0" axis="1 0 0" range="-10 10" limited="true" class="AIE_joint" />
                  <site name="left_foot" pos="0.00000 0.00000 0.00000" size="0.01" rgba="1 0 0 0.5" />
                  <site name="L_foot_imu" size="0.01" pos="0.16300 0.02400 -0.06000" />
  
                  <!-- Multi-point contact system for left foot -->
                  <!-- Back-right corner -->
                  <geom name="L_foot_contact_br" type="sphere" size="0.0001" pos="0.05000 -0.0600 -0.11900" class="foot_collision"/>
                  <geom name="L_foot_visual_br" type="sphere" size="0.01" pos="0.05000 -0.0600 -0.11900" contype="0" conaffinity="0" group="1" density="0" rgba="1 0 0 0.5"/>
                  
                  <!-- Back-left corner -->
                  <geom name="L_foot_contact_bl" type="sphere" size="0.0001" pos="0.05000 0.0600 -0.11900" class="foot_collision"/>
                  <geom name="L_foot_visual_bl" type="sphere" size="0.01" pos="0.05000 0.0600 -0.11900" contype="0" conaffinity="0" group="1" density="0" rgba="1 0 0 0.5"/>
                  
                  <!-- Front-right corner -->
                   <geom name="L_foot_contact_fr" type="sphere" size="0.0001" pos="0.3600 -0.0600 -0.11000" class="foot_collision"/>
                  <geom name="L_foot_visual_fr" type="sphere" size="0.01" pos="0.3600 -0.0600 -0.11000" contype="0" conaffinity="0" group="1" density="0" rgba="1 0 0 0.5"/>
                  
                  <!-- Front-left corner -->
                  <geom name="L_foot_contact_fl" type="sphere" size="0.0001" pos="0.3600 0.0600 -0.11000" class="foot_collision"/>
                  <geom name="L_foot_visual_fl" type="sphere" size="0.01" pos="0.3600 0.0600 -0.11000" contype="0" conaffinity="0" group="1" density="0" rgba="1 2 2 2"/>
                  <!-- Mid-back-left -->
                  <geom name="L_foot_contact_mbl" type="sphere" size="0.0001" pos="0.22250 -0.06500 -0.11350" class="foot_collision"/>
                  <geom name="L_foot_visual_mbl" type="sphere" size="0.01" pos="0.22250 -0.06500 -0.11350" contype="0" conaffinity="0" group="1" density="0" rgba="1 0 0 0.5"/>
                  
                  <!-- Mid-back-right -->
                  <geom name="L_foot_contact_mbr" type="sphere" size="0.0001" pos="0.22250 0.06500 -0.11350" class="foot_collision"/>
                  <geom name="L_foot_visual_mbr" type="sphere" size="0.01" pos="0.22250 0.06500 -0.11350" contype="0" conaffinity="0" group="1" density="0" rgba="1 0 0 0.5"/>
                  
                  <geom name="L_Foot" type="mesh" mesh="L_Sole" />
                  
                  <!-- Touch sensor sites -->
                  <site name="sp0" pos="0.05000 -0.0600 -0.11900" type="sphere" size=".01" group="10" />
                  <site name="sp1" pos="0.05000 0.0600 -0.11900" type="sphere" size=".01" group="10" />
                  <site name="sp2" pos="0.3600 -0.05500 -0.11000" type="sphere" size=".01" group="10" />
                  <site name="sp3" pos="0.3600 0.05500 -0.11000" type="sphere" size=".01" group="10" />



                        <body> <geom type="box" pos="0.151 0 -.045" size="0.15 0.04 0.02"/> </body>

                        </body>
                    </body>
                    </body>
                </body>
                </body>

                <!--  RIGHT LEG -->
        <body name="R_hip" pos="0.00400 -0.09200 -0.20000">
          <inertial mass="3.363" pos="0.11200 -0.17000 0.00700" fullinertia="0.11230 0.08360 0.18680 0.08410 -0.00300 0.00320" />
          <joint name="right_hip_aa" axis="1 0 0" range="-20 10" limited="true" class="HAA_joint" />
          <site name="tor_R_HAA" size="0.01" pos="0.00000 0.00000 0.00000" />
          <site name="pos_R_HAA" size="0.01" pos="0.00000 0.00000 0.00000" />
          <site name="R_hip_imu" size="0.01" pos="0.11200 -0.17000 0.00700" />
          
          <geom name="R_Hip" type="mesh" mesh="R_Hip"  />
          <geom name="R_Hip_ellipsoid" type="ellipsoid" size="0.10 0.12 0.08" pos="0.08 -0.12 0" material="march_grey" class="R_collision"/>



          <body name="R_UL" pos="0.17600 -0.24900 0.00100">
            <inertial mass="4.473" pos=" 0.01000 0.06600 -0.22600" fullinertia="0.46570 0.44360 0.03460 -0.00320 0.01130 0.09930" />
            <joint name="right_hip_fe" axis="0 -1 0" range="-20 115" limited="true" class="rotational_joint" />
            <site name="tor_R_HFE" size="0.01" pos="0.00000 0.00000 0.00000" />
            <site name="pos_R_HFE" size="0.01" pos="0.00000 0.00000 0.00000" />
            <site name="R_UL_imu" size="0.01" pos="0.01000 0.06600 -0.22600" />
  
            <geom name="R_UpperLeg" type="mesh" mesh="R_UpperLeg" />
            <geom name="R_UpperLeg_ellipsoid" type="ellipsoid" size="0.08 0.08 0.24" pos="0 0.04 -0.235" material="march_grey" class="R_collision"/>


                    <body> <geom type="capsule" fromto="0 0.125 0 0 0.175 -0.45" size="0.075" mass="8.44"/> </body>

            <body name="R_LL" pos="0.00200 0.0600 -0.47200">
              <inertial mass="4.973" pos=" 0.00800 0.03900 -0.14100" fullinertia="0.21540 0.22000 0.03000 -0.00140 -0.00290 0.03550" />
              <joint name="right_knee" axis="0 1 0" range="0 125" limited="true" class="rotational_joint" />
              <site name="tor_R_KFE" size="0.01" pos="0.00000 0.00000 0.00000" />
              <site name="pos_R_KFE" size="0.01" pos="0.00000 0.00000 0.00000" />
              <site name="R_LL_imu" size="0.01" pos="0.00800 0.03900 -0.14100" />
         
              <geom name="R_LowerLeg" type="mesh" mesh="R_LowerLeg" />
              <geom name="R_LowerLeg_ellipsoid" type="ellipsoid" size="0.07 0.07 0.23" pos="0 0.015 -0.23" material="march_grey" class="R_collision"/>


                    <body> <geom type="capsule" fromto="0 0.1 0 0 0.08 -0.5" size="0.05" mass="2.3"/> </body>

             <body name="R_ankle" pos="0.00200 0.02500 -0.46800">
                <inertial mass="0.515" pos=" 0.00400 0.06000 -0.01800" fullinertia="0.00240 0.00270 0.00460 0.00010 0.00000 0.00060" />
                <joint name="right_ankle_dpf" axis="0 -1 0" range="-28 17" limited="true" class="AIE_joint" />
                <site name="pos_R_ankle" size="0.01" pos="0.00000 0.00000 0.00000" />
                <site name="tor_R_ADPF" size="0.01" pos="0.00000 0.00000 0.00000" />
                <site name="tor_R_AIE" size="0.01" pos="-0.13100 0.11400 -0.02600" />
                <site name="R_ankle_imu" size="0.01" pos="0.00400 0.06000 -0.01800" />
                    
                <geom name="R_Ankle" type="mesh" mesh="R_Ankle" />
                <geom name="R_Ankle_ellipsoid" type="ellipsoid" size="0.07 0.06 0.04" pos="0 0.06 -0.015" material="march_grey" class="R_collision"/>


                <body name="R_foot" pos="-0.13500 0.1200 -0.02600">
                    <joint name="right_ankle_ie" pos="-0.0 0.0 -0.0" axis="-1 0 0" range="-10 10" limited="true" class="AIE_joint" /> 
                  <inertial mass="4.440" pos=" 0.16700 -0.02600 -0.06100" fullinertia="0.04700 0.19280 0.17840 0.01520 0.04800 0.00080" />
                  <geom name="R_Foot" type="mesh" mesh="R_Sole" />
                  <site name="right_foot" pos="0.00000 0.00000 0.00000" size="0.01" rgba="1 0 0 0.5" />
                  <site name="R_foot_imu" size="0.01" pos="0.16700 -0.02600 -0.06100" />

    
                  <!-- Multi-point contact system for right foot -->
                  <!-- Back-left corner -->
                  <!-- Back-left corner -->
                   <!-- Since axis = -1, a negative y value means its shifted towards the right, so its opposite to the left foot -->
                  <geom name="R_foot_contact_br" type="sphere" size="0.0001" pos="0.05000 -0.0600 -0.11900" class="foot_collision"/>
                  <geom name="R_foot_visual_br" type="sphere" size="0.01" pos="0.05000 -0.0600 -0.11900" contype="0" conaffinity="0" group="1" density="0" rgba="1 0 0 0.5"/>
                  
                  <!-- Back-right corner -->
                  <geom name="R_foot_contact_bl" type="sphere" size="0.0001" pos="0.05000 0.0600 -0.11900" class="foot_collision"/>
                  <geom name="R_foot_visual_bl" type="sphere" size="0.01" pos="0.05000 0.0600 -0.11900" contype="0" conaffinity="0" group="1" density="0" rgba="1 0 0 0.5"/>
                  
                  <!-- Front-left corner -->
                  <geom name="R_foot_contact_fr" type="sphere" size="0.0001" pos="0.3600 -0.0600 -0.11000" class="foot_collision"/>
                  <geom name="R_foot_visual_fr" type="sphere" size="0.01" pos="0.3600 -0.0600 -0.11000" contype="0" conaffinity="0" group="1" density="0" rgba="1 0 0 0.5"/>
                  
                  <!-- Front-right corner -->
                  <geom name="R_foot_contact_fl" type="sphere" size="0.0001" pos="0.3600 0.0600 -0.11000" class="foot_collision"/>
                  <geom name="R_foot_visual_fl" type="sphere" size="0.01" pos="0.3600 0.0600 -0.11000" contype="0" conaffinity="0" group="1" density="0" rgba="1 0 0 0.5"/>
                  <!-- Mid-back-left -->
                  <geom name="R_foot_contact_mbr" type="sphere" size="0.0001" pos="0.22250 -0.06500 -0.11350" class="foot_collision"/>
                  <geom name="R_foot_visual_mbr" type="sphere" size="0.01" pos="0.22250 -0.06500 -0.11350" contype="0" conaffinity="0" group="1" density="0" rgba="1 0 0 0.5"/>
                  
                  <!-- Mid-back-right -->
                  <geom name="R_foot_contact_mbl" type="sphere" size="0.0001" pos="0.22250 0.06500 -0.11350" class="foot_collision"/>
                  <geom name="R_foot_visual_mbl" type="sphere" size="0.01" pos="0.22250 0.06500 -0.11350" contype="0" conaffinity="0" group="1" density="0" rgba="1 0 0 0.5"/>
                  
                  <!-- Touch sensor sites -->
                  <site name="sp4" pos="0.05000 -0.0600 -0.11900" type="sphere" size=".01" group="10" />
                  <site name="sp5" pos="0.05000 0.0600 -0.11900" type="sphere" size=".01" group="10" />
                  <site name="sp6" pos="0.3600 -0.05500 -0.11000" type="sphere" size=".01" group="10" />
                  <site name="sp7" pos="0.3600 0.05500 -0.11000" type="sphere" size=".01" group="10" />


                        <body> <geom type="box" pos="0.151 0 -.045" size="0.15 0.04 0.02"/> </body>

                        </body>
                    </body>
                    </body>
                </body>
                </body>
            </body>
            </body>
            <!-- ZMP Marker on the floor -->
            <body name="zmp_marker" pos="0 0 0.001" mocap="true">
                <geom name="zmp_sphere" type="sphere" size="0.03" rgba="1 0 0 1" contype="0" conaffinity="0"/>
                <site name="zmp_site" size="0.001" pos="0 0 0"/>
            </body>
        </worldbody></mujoco>